terminate called after throwing an instance of 'std::logic_error'
  what():  Chance::dice - max can't be 0
FAILED: ./habit world_9_0 -seed 1 -pi 1 -k 1 -slx -7 -sly -1 -pr 0
